Workbook

Sheet Instructions
B2: Resource Forecasting Model Workbook
B3: This workbook is intended to be used with the Resource Forecasting Model App found here | T3: *Efficiency Factors have been adjusted to default to the MPG work requirements
B5: WORKBOOK INSTRUCTIONS | D5: RESOURCE MODEL INSTRUCTIONS | T5: Resourcing Dash > Resources > KPI's >
B6: 1. Review and complete all tabs in this workbook | D6: 1. The Resource Model contains three tabs for analyzing and visualizing the aggregated resources.
B7: 1.1 Populate the Project List on the "Projects" tab and follow instructions at top of page.
B8: 1.2 Review "Duration Table" tab and follow instructions at top of page.
B9: 1.3 Review "Program Resources" tab and follow instructions at top of page.
B10: 1.4 Review Project Archetype tabs (blue tabs) and follow instructions at top of pages.
B11: 2. Once the above steps are complete, save this workbook.
B12: 3. Open the MPG Resourcing App (Link) and upload the saved workbook.
B13: 3.1 Under "Aggregation", select the time-interval for which you'd like the resource data to be summarized to. (For example, if "quarter" is selected, each bar in the model's charts will represent one quarter)
D17: 2. Scaling Factors may be applied to resources to scale them up or down according to project value. A scaling factor less than one indicates less resources are required. A scaling factor greater than one indicates more resources are required.
B26: 3.2 Click the "Upload" icon in the middle of the page and select the saved workbook.
B27: 3.3. Upon uploading the workbook, the model will take a few minutes to process the data
D38: 3. Data may be viewed in table format and downloaded as a .csv file below any of the charts
D52: 4. Apply Filters to drill down into the data. Filters will also be applied to the data tables below the charts.

Sheet Projects
A9: PROJECT LIST
A10: Program Name | B10: Project Name | C10: Portfolio | D10: OpCo | E10: Project Archetype | F10: Cost ($M) | G10: Project Kickoff | H10: Engineering Start | I10: Engineering Finish | J10: ISD | K10: Project Finish
A11: Highlands Buildout | B11: High Plains Intertie | C11: Linear Assets | D11: PSCo | E11: Transmission and Distribution | F11: 213.46973 | G11: 46235 | H11: 46327 | J11: 46631
A12: Highlands Buildout | B12: Canyon Crest Feeder Upgrade | C12: Linear Assets | D12: PSCo | E12: Transmission and Distribution | F12: 37.723744 | G12: 46235 | H12: 46266 | J12: 46691
A13: Urban Renewal | B13: Summit Crest 115‑kV Station | C13: Linear Assets | D13: SPS | E13: Substation | F13: 146 | G13: 46235 | H13: 46310 | J13: 46722
A14: Urban Renewal | B14: Canyon Winds Energy Center | C14: Fixed Assets | D14: PSCo | E14: Wind | F14: 345 | G14: 46235 | H14: 46236 | I14: 46478 | J14: 46966
A15: Urban Renewal | B15: Crystal Falls Turbine Renewal | C15: Fixed Assets | D15: PSCo | E15: Hydro | F15: 222 | J15: 47062
A16: Southwest Energy Supply | B16: Copper Ridge BESS Upgrade | C16: Fixed Assets | D16: SPS | E16: BESS | F16: 111 | G16: 46266 | H16: 46310 | J16: 47102
A17: Highlands Buildout | B17: High Plains 230‑kV Interconnect | C17: Linear Assets | D17: NSP | E17: Substation | F17: 188 | G17: 46266 | H17: 46327 | J17: 47102
A18: Southwest Energy Supply | B18: Redstone Thermal Repower | C18: Fixed Assets | D18: NSP | E18: Thermal | F18: 642 | G18: 46296 | H18: 46357 | J18: 47116
A19: Circuit 9991 | B19: Silverline Substation Expansion | C19: Linear Assets | D19: PSCo | E19: Transmission and Distribution | F19: 132.30227 | I19: 46874 | J19: 47170
A20: Circuit 9991 | B20: Aurora Grid Upgrade | C20: Linear Assets | D20: PSCo | E20: Transmission and Distribution | F20: 187.68892 | G20: 46296 | H20: 46357 | J20: 47257
A21: Southwest Energy Supply | B21: Canyon Crest CHP Project | C21: Fixed Assets | D21: NSP | E21: Thermal | F21: 170 | J21: 47270
A22: Highlands Buildout | B22: Desert Bloom Solar Array | C22: Fixed Assets | D22: NSP | E22: Solar | F22: 423.42226 | G22: 46235 | H22: 46327 | J22: 47298
A23: Urban Gas Upgrades | B23: Mesa Valley Gas Reliability | C23: Linear Assets | D23: PSCo | E23: Gas | F23: 84 | G23: 46388 | H23: 46478 | J23: 47321
A24: Highlands Buildout | B24: Canyon Ridge Substation Expansion | C24: Linear Assets | D24: SPS | E24: Substation | F24: 80 | J24: 47331
A25: Urban Gas Upgrades | B25: Ironhorse Gas Reinforcement | C25: Linear Assets | D25: PSCo | E25: Gas | F25: 44 | J25: 47331
A26: Southwest Energy Supply | B26: Prairie Gale Wind Park | C26: Fixed Assets | D26: SPS | E26: Wind | F26: 612 | G26: 46249 | J26: 47331
A27: Southwest Energy Supply | B27: Sunridge Solar Farm | C27: Fixed Assets | D27: SPS | E27: Solar | F27: 447.73334 | J27: 47376
A28: Southwest Energy Supply | B28: Riverbend Intake Upgrade | C28: Fixed Assets | D28: PSCo | E28: Hydro | F28: 225.12787 | J28: 47387
A29: Urban Renewal | B29: Redstone Valley Substation Upgrade | C29: Linear Assets | D29: PSCo | E29: Substation | F29: 49 | G29: 46296 | H29: 46357 | J29: 47467
A30: Circuit 9991 | B30: Northstar Transmission Loop | C30: Linear Assets | D30: PSCo | E30: Transmission and Distribution | F30: 312.16386 | G30: 46296 | I30: 46508 | J30: 47475
A31: Southwest Energy Supply | B31: Horizon Flats Solar Expansion | C31: Fixed Assets | D31: NSP | E31: Solar | F31: 189.33303 | J31: 47483
A32: Urban Gas Upgrades | B32: Sagebrush Lateral Extension | C32: Linear Assets | D32: PSCo | E32: Gas | F32: 78.177794 | G32: 46235 | H32: 46508 | I32: 46966 | J32: 47517
A33: Urban Gas Upgrades | B33: Timberline Storage Expansion | C33: Linear Assets | D33: PSCo | E33: Gas | F33: 38.498486 | G33: 46235 | J33: 47568
A34: Highlands Buildout | B34: Pioneer Ridge Line Rebuild | C34: Linear Assets | D34: PSCo | E34: Transmission and Distribution | F34: 65.513579 | J34: 47605
A35: Urban Gas Upgrades | B35: Frontier Peak Metering Project | C35: Linear Assets | D35: PSCo | E35: Gas | F35: 148.16043 | J35: 47625
A36: Highlands Buildout | B36: Golden Mesa Solar Park | C36: Fixed Assets | D36: PSCo | E36: Solar | F36: 113.39808 | J36: 47665
A37: Southwest Energy Supply | B37: Northgate Substation Rebuild | C37: Linear Assets | D37: PSCo | E37: Substation | F37: 115 | J37: 47696
A38: Urban Gas Upgrades | B38: Redwood Compression Upgrade | C38: Linear Assets | D38: PSCo | E38: Gas | F38: 166.28369 | J38: 47983
A39: Highlands Buildout | B39: Skytrail Ridge Wind Project | C39: Fixed Assets | D39: PSCo | E39: Wind | F39: 452 | J39: 48044
A40: Urban Gas Upgrades | B40: Copper Trail Pipeline Integrity | C40: Linear Assets | D40: PSCo | E40: Gas | F40: 53.468864 | J40: 48081
A41: Southwest Energy Supply | B41: Summit Lake Hydro Expansion | C41: Fixed Assets | D41: PSCo | E41: Hydro | F41: 151.93187 | J41: 48090

Sheet Duration Table
C2: DURATION TABLE
D4: Duration (Months) by Project Archetype / Cost
C5: Project Archetype | D5: <$50M | E5: $50- $100M | F5: $100-$500M | G5: $500-$1000M | H5: $1000M+
D6: 0 | E6: 50 | F6: 100 | G6: 500 | H6: 1000
C7: Solar | D7: 18 | E7: 30 | F7: 36 | G7: 42 | H7: 48
C8: BESS | D8: 18 | E8: 30 | F8: 36 | G8: 42 | H8: 48
C9: Substation | D9: 24 | E9: 24 | F9: 30 | G9: 36 | H9: 42
C10: Transmission and Distribution | D10: 18 | E10: 30 | F10: 36 | G10: 42 | H10: 54
C11: Gas | D11: 24 | E11: 30 | F11: 36 | G11: 42 | H11: 48
C12: Wind | D12: 18 | E12: 30 | F12: 36 | G12: 42 | H12: 54
C13: Hydro | D13: 24 | E13: 24 | F13: 30 | G13: 36 | H13: 42
C14: Thermal | D14: 24 | E14: 24 | F14: 30 | G14: 36 | H14: 42
C15: Biomass | D15: 24 | E15: 24 | F15: 30 | G15: 36 | H15: 42
C16: New Archetype 1
C17: New Archetype 2

Sheet Program Resources
B2: PROGRAM RESOURCES
E4: Startup | F4: Execution | G4: Closeout
E5: =E6/24 -> 0.0041666667 | G5: =G6/24 -> 0.0041666667
D6: % of Program Duration: | E6: 0.1 | F6: 0.8 | G6: 0.1
B7: Resource Title | C7: Team | D7: Resource Type | E7: Startup | F7: Execution | G7: Closeout
B8: Program Director | C8: Program | D8: Program Management | E8: 1 | F8: 0.75 | G8: 0.5
B9: Program Operations Lead | C9: Program | D9: Program Management | E9: 0 | F9: 0 | G9: 0
B10: Initiation Lead | C10: Program | D10: Program Management | E10: 1 | F10: 0 | G10: 0
B11: CM Manager | C11: Program | D11: Program Construction Management | E11: 0.25 | F11: 0.75 | G11: 0.5
B12: CM SPS Lead | C12: SPS | D12: Program Construction Management | E12: 0 | F12: 0.75 | G12: 0.5
B13: CM NSP Lead | C13: NSP | D13: Program Construction Management | E13: 0 | F13: 0.75 | G13: 0.5
B14: CM PSCo Lead | C14: PSCo | D14: Program Construction Management | E14: 0 | F14: 0.75 | G14: 0.5
B15: H&S Lead | C15: Program | D15: Program Construction Management | E15: 0.25 | F15: 0.75 | G15: 0
B16: Engineering Manager | C16: Program | D16: Program Engineering | E16: 0.25 | F16: 0.75 | G16: 0.5
B17: SPS Engr Lead | C17: SPS | D17: Program Engineering | E17: 0 | F17: 0 | G17: 0
B18: NSP Engr Lead | C18: NSP | D18: Program Engineering | E18: 0 | F18: 0 | G18: 0
B19: PSCO Engr Lead | C19: PSCo | D19: Program Engineering | E19: 0 | F19: 0 | G19: 0
... B32: Finance Lead | C32: Program | D32: Program Management | E32: 0 | F32: 0 | G32: 0

Sheet Transmission and Distribution
B2: PROJECT ARCHETYPE: | C2: Transmission and Distribution
B4: Resource Name | C4: Project Archetype | D4: Resource Category | E4: Planning | K4: Design & Engineering | Q4: Construction | AC4: Closeout
B5: Column1 | C5: Column2 | D5: Column3 | E5: 1 | F5: 2 | G5: 3 | H5: 4 | I5: 5 | J5: 6 | K5: 7 | L5: 8 | M5: 9 | N5: 10 | O5: 11 | P5: 12 | Q5: 13 | R5: 14 | S5: 15 | T5: 16 | U5: 17 | V5: 18 | W5: 19 | X5: 20 | Y5: 21 | Z5: 22 | AA5: 23 | AB5: 24 | AC5: 25 | AD5: 26 | AE5: 27
B6: Project Manager | C6: =$C$2 -> Transmission and Distribution | D6: Project Management | E6: 0.25 | F6: 0.25 | G6: 0.25 | H6: 0.45 | I6: 0.45 | J6: 0.45 | K6: 0.65 | L6: 0.65 | M6: 0.65 | N6: 0.85 | O6: 0.85 | P6: 0.85 | Q6: 0.85 | R6: 0.85 | S6: 0.85 | T6: 0.85 | U6: 0.85 | V6: 0.85 | W6: 0.85 | X6: 0.85 | Y6: 0.85 | Z6: 0.85 | AA6: 0.85 | AB6: 0.85 | AC6: 0.5 | AD6: 0.4 | AE6: 0.25
B7: Project Engineer | C7: =$C$2 -> Transmission and Distribution | D7: Project Management | E7: 0.05 | F7: 0.05 | G7: 0.05 | H7: 0.05 | I7: 0.05 | J7: 0.05 | K7: 0.05 | L7: 0.05 | M7: 0.05 | N7: 0.05 | O7: 0.05 | P7: 0.05 | Q7: 0.05 | R7: 0.05 | S7: 0.05 | T7: 0.05 | U7: 0.05 | V7: 0.05 | W7: 0.05 | X7: 0.05 | Y7: 0.05 | Z7: 0.05 | AA7: 0.05 | AB7: 0.05 | AC7: 0.05 | AD7: 0.05 | AE7: 0.05
B8: Project Coordinator | C8: =$C$2 -> Transmission and Distribution | D8: Project Management | E8: 0.05 | F8: 0.05 | G8: 0.1 | H8: 0.1 | I8: 0.15 | J8: 0.15 | K8: 0.25 | L8: 0.25 | M8: 0.25 | N8: 0.25 | O8: 0.25 | P8: 0.25 | Q8: 0.25 | R8: 0.25 | S8: 0.25 | T8: 0.25 | U8: 0.25 | V8: 0.25 | W8: 0.25 | X8: 0.25 | Y8: 0.25 | Z8: 0.25 | AA8: 0.25 | AB8: 0.25 | AC8: 0.25 | AD8: 0.25 | AE8: 0.25
B9: Overhead OE Transmission Line Engineer | C9: =$C$2 -> Transmission and Distribution | D9: Engineering | E9: 0.05 | F9: 0.05 | G9: 0.05 | H9: 0.05 | I9: 0.05 | J9: 0.05 | K9: 0.1 | L9: 0.1 | M9: 0.1 | N9: 0.1 | O9: 0.1 | P9: 0.1 | Q9: 0.1 | R9: 0.1 | S9: 0.1 | T9: 0.1 | U9: 0.1 | V9: 0.1 | W9: 0.1 | X9: 0.1 | Y9: 0.1 | Z9: 0.1 | AA9: 0.1 | AB9: 0.1 | AC9: 0.05 | AD9: 0.05 | AE9: 0
B10: Underground OE Transmission Line Engineer | C10: =$C$2 -> Transmission and Distribution | D10: Engineering | E10: 0.05 | F10: 0.05 | G10: 0.05 | H10: 0.05 | I10: 0.05 | J10: 0.05 | K10: 0.1 | L10: 0.1 | M10: 0.1 | N10: 0.1 | O10: 0.1 | P10: 0.1 | Q10: 0.1 | R10: 0.1 | S10: 0.1 | T10: 0.1 | U10: 0.1 | V10: 0.1 | W10: 0.1 | X10: 0.1 | Y10: 0.1 | Z10: 0.1 | AA10: 0.1 | AB10: 0.1 | AC10: 0.05 | AD10: 0.05 | AE10: 0
B11: Mechanical Engineer | C11: =$C$2 -> Transmission and Distribution | D11: Engineering | E11: 0.05 | F11: 0.05 | G11: 0.05 | H11: 0.05 | I11: 0.05 | J11: 0.05 | K11: 0.1 | L11: 0.1 | M11: 0.1 | N11: 0.1 | O11: 0.1 | P11: 0.1 | Q11: 0.1 | R11: 0.1 | S11: 0.1 | T11: 0.1 | U11: 0.1 | V11: 0.1 | W11: 0.1 | X11: 0.1 | Y11: 0.1 | Z11: 0.1 | AA11: 0.1 | AB11: 0.1 | AC11: 0.05 | AD11: 0.05 | AE11: 0
B12: Construction Manager | C12: =$C$2 -> Transmission and Distribution | D12: Construction Monitoring | E12: 0 | F12: 0 | G12: 0 | H12: 0.25 | I12: 0.25 | J12: 0.25 | K12: 0.5 | L12: 0.5 | M12: 0.5 | N12: 0.75 | O12: 0.75 | P12: 0.75 | Q12: 0.75 | R12: 0.75 | S12: 0.75 | T12: 0.75 | U12: 0.75 | V12: 0.75 | W12: 0.75 | X12: 0.75 | Y12: 0.75 | Z12: 0.75 | AA12: 0.75 | AB12: 0.75 | AC12: 0.5 | AD12: 0.4 | AE12: 0.25
B13: H&S Field | C13: =$C$2 -> Transmission and Distribution | D13: Construction Monitoring | E13: 0 | F13: 0 | G13: 0 | H13: 0 | I13: 0 | J13: 0 | K13: 0 | L13: 0 | M13: 0 | N13: 0 | O13: 0 | P13: 0 | Q13: 0.5 | R13: 0.5 | S13: 0.5 | T13: 0.5 | U13: 0.5 | V13: 0.5 | W13: 0.5 | X13: 0.5 | Y13: 0.5 | Z13: 0.5 | AA13: 0.5 | AB13: 0.5 | AC13: 0.25 | AD13: 0.15 | AE13: 0
B14: Estimator | C14: =$C$2 -> Transmission and Distribution | D14: Project Controls | E14: 0.1 | F14: 0.1 | G14: 0.1 | H14: 0.1 | I14: 0.1 | J14: 0.1 | K14: 0.15 | L14: 0.15 | M14: 0.15 | N14: 0.15 | O14: 0.15 | P14: 0.15 | Q14: 0.1 | R14: 0.1 | S14: 0.1 | T14: 0.1 | U14: 0.1 | V14: 0.1 | W14: 0.1 | X14: 0.1 | Y14: 0.1 | Z14: 0.1 | AA14: 0.1 | AB14: 0.1 | AC14: 0.05 | AD14: 0.05 | AE14: 0.05
B15: Risk Analyst | C15: =$C$2 -> Transmission and Distribution | D15: Project Controls | E15: 0.1 | F15: 0.1 | G15: 0.1 | H15: 0.1 | I15: 0.1 | J15: 0.1 | K15: 0.1 | L15: 0.1 | M15: 0.1 | N15: 0.1 | O15: 0.1 | P15: 0.1 | Q15: 0.1 | R15: 0.1 | S15: 0.1 | T15: 0.1 | U15: 0.1 | V15: 0.1 | W15: 0.1 | X15: 0.1 | Y15: 0.1 | Z15: 0.1 | AA15: 0.1 | AB15: 0.1 | AC15: 0.05 | AD15: 0.05 | AE15: 0.05
B16: Document Control Specialist | C16: =$C$2 -> Transmission and Distribution | D16: Project Controls | E16: 0.1 | F16: 0.1 | G16: 0.1 | H16: 0.1 | I16: 0.1 | J16: 0.1 | K16: 0.1 | L16: 0.1 | M16: 0.1 | N16: 0.1 | O16: 0.1 | P16: 0.1 | Q16: 0.2 | R16: 0.2 | S16: 0.2 | T16: 0.2 | U16: 0.2 | V16: 0.2 | W16: 0.2 | X16: 0.2 | Y16: 0.2 | Z16: 0.2 | AA16: 0.2 | AB16: 0.2 | AC16: 0.25 | AD16: 0.25 | AE16: 0.25
B17: Scheduler | C17: =$C$2 -> Transmission and Distribution | D17: Project Controls | E17: 0.2 | F17: 0.2 | G17: 0.2 | H17: 0.2 | I17: 0.2 | J17: 0.2 | K17: 0.2 | L17: 0.2 | M17: 0.2 | N17: 0.2 | O17: 0.2 | P17: 0.2 | Q17: 0.2 | R17: 0.2 | S17: 0.2 | T17: 0.2 | U17: 0.2 | V17: 0.2 | W17: 0.2 | X17: 0.2 | Y17: 0.2 | Z17: 0.2 | AA17: 0.2 | AB17: 0.2 | AC17: 0.05 | AD17: 0.05 | AE17: 0.05
B18: Cost Controls | C18: =$C$2 -> Transmission and Distribution | D18: Project Controls | E18: 0.2 | F18: 0.2 | G18: 0.2 | H18: 0.2 | I18: 0.2 | J18: 0.2 | K18: 0.45 | L18: 0.45 | M18: 0.45 | N18: 0.45 | O18: 0.45 | P18: 0.45 | Q18: 0.45 | R18: 0.45 | S18: 0.45 | T18: 0.45 | U18: 0.45 | V18: 0.45 | W18: 0.45 | X18: 0.45 | Y18: 0.45 | Z18: 0.45 | AA18: 0.45 | AB18: 0.45 | AC18: 0.15 | AD18: 0.15 | AE18: 0.15

Sheet Substation
B2: PROJECT ARCHETYPE: | C2: Substation
B4: Resource Name | C4: Project Archetype | D4: Resource Category | E4: Planning | K4: Design & Engineering | Q4: Construction | AC4: Closeout
B5: Column1 | C5: Column2 | D5: Column3 | E5: 1 | F5: 2 | G5: 3 | H5: 4 | I5: 5 | J5: 6 | K5: 7 | L5: 8 | M5: 9 | N5: 10 | O5: 11 | P5: 12 | Q5: 13 | R5: 14 | S5: 15 | T5: 16 | U5: 17 | V5: 18 | W5: 19 | X5: 20 | Y5: 21 | Z5: 22 | AA5: 23 | AB5: 24 | AC5: 25 | AD5: 26 | AE5: 27
B6: Project Manager | C6: =$C$2 -> Substation | D6: Project Management | E6: 0.25 | F6: 0.25 | G6: 0.25 | H6: 0.45 | I6: 0.45 | J6: 0.45 | K6: 0.65 | L6: 0.65 | M6: 0.65 | N6: 0.85 | O6: 0.85 | P6: 0.85 | Q6: 0.85 | R6: 0.85 | S6: 0.85 | T6: 0.85 | U6: 0.85 | V6: 0.85 | W6: 0.85 | X6: 0.85 | Y6: 0.85 | Z6: 0.85 | AA6: 0.85 | AB6: 0.85 | AC6: 0.5 | AD6: 0.4 | AE6: 0.25
B7: Project Engineer | C7: =$C$2 -> Substation | D7: Project Management | E7: 0.05 | F7: 0.05 | G7: 0.05 | H7: 0.05 | I7: 0.05 | J7: 0.05 | K7: 0.05 | L7: 0.05 | M7: 0.05 | N7: 0.05 | O7: 0.05 | P7: 0.05 | Q7: 0.05 | R7: 0.05 | S7: 0.05 | T7: 0.05 | U7: 0.05 | V7: 0.05 | W7: 0.05 | X7: 0.05 | Y7: 0.05 | Z7: 0.05 | AA7: 0.05 | AB7: 0.05 | AC7: 0.05 | AD7: 0.05 | AE7: 0.05
B8: Project Coordinator | C8: =$C$2 -> Substation | D8: Project Management | E8: 0.05 | F8: 0.05 | G8: 0.1 | H8: 0.1 | I8: 0.15 | J8: 0.15 | K8: 0.25 | L8: 0.25 | M8: 0.25 | N8: 0.25 | O8: 0.25 | P8: 0.25 | Q8: 0.25 | R8: 0.25 | S8: 0.25 | T8: 0.25 | U8: 0.25 | V8: 0.25 | W8: 0.25 | X8: 0.25 | Y8: 0.25 | Z8: 0.25 | AA8: 0.25 | AB8: 0.25 | AC8: 0.25 | AD8: 0.25 | AE8: 0.25
B9: Civil Engineer | C9: =$C$2 -> Substation | D9: Engineering | E9: 0.05 | F9: 0.05 | G9: 0.05 | H9: 0.05 | I9: 0.05 | J9: 0.05 | K9: 0.1 | L9: 0.1 | M9: 0.1 | N9: 0.1 | O9: 0.1 | P9: 0.1 | Q9: 0.1 | R9: 0.1 | S9: 0.1 | T9: 0.1 | U9: 0.1 | V9: 0.1 | W9: 0.1 | X9: 0.1 | Y9: 0.1 | Z9: 0.1 | AA9: 0.1 | AB9: 0.1 | AC9: 0.05 | AD9: 0.05 | AE9: 0
B10: OE Substation Grading Engineer | C10: =$C$2 -> Substation | D10: Engineering | E10: 0.05 | F10: 0.05 | G10: 0.05 | H10: 0.05 | I10: 0.05 | J10: 0.05 | K10: 0.1 | L10: 0.1 | M10: 0.1 | N10: 0.1 | O10: 0.1 | P10: 0.1 | Q10: 0.1 | R10: 0.1 | S10: 0.1 | T10: 0.1 | U10: 0.1 | V10: 0.1 | W10: 0.1 | X10: 0.1 | Y10: 0.1 | Z10: 0.1 | AA10: 0.1 | AB10: 0.1 | AC10: 0.05 | AD10: 0.05 | AE10: 0
B11: P&C System Protection & Settings Engineer | C11: =$C$2 -> Substation | D11: Engineering | E11: 0.05 | F11: 0.05 | G11: 0.05 | H11: 0.05 | I11: 0.05 | J11: 0.05 | K11: 0.1 | L11: 0.1 | M11: 0.1 | N11: 0.1 | O11: 0.1 | P11: 0.1 | Q11: 0.1 | R11: 0.1 | S11: 0.1 | T11: 0.1 | U11: 0.1 | V11: 0.1 | W11: 0.1 | X11: 0.1 | Y11: 0.1 | Z11: 0.1 | AA11: 0.1 | AB11: 0.1 | AC11: 0.05 | AD11: 0.05 | AE11: 0
B12: P&C Automation & Integration Engineer | C12: =$C$2 -> Substation | D12: Engineering | E12: 0.05 | F12: 0.05 | G12: 0.05 | H12: 0.05 | I12: 0.05 | J12: 0.05 | K12: 0.1 | L12: 0.1 | M12: 0.1 | N12: 0.1 | O12: 0.1 | P12: 0.1 | Q12: 0.1 | R12: 0.1 | S12: 0.1 | T12: 0.1 | U12: 0.1 | V12: 0.1 | W12: 0.1 | X12: 0.1 | Y12: 0.1 | Z12: 0.1 | AA12: 0.1 | AB12: 0.1 | AC12: 0.05 | AD12: 0.05 | AE12: 0
B13: OE Substation Structural Engineer | C13: =$C$2 -> Substation | D13: Engineering | E13: 0.05 | F13: 0.05 | G13: 0.05 | H13: 0.05 | I13: 0.05 | J13: 0.05 | K13: 0.1 | L13: 0.1 | M13: 0.1 | N13: 0.1 | O13: 0.1 | P13: 0.1 | Q13: 0.1 | R13: 0.1 | S13: 0.1 | T13: 0.1 | U13: 0.1 | V13: 0.1 | W13: 0.1 | X13: 0.1 | Y13: 0.1 | Z13: 0.1 | AA13: 0.1 | AB13: 0.1 | AC13: 0.05 | AD13: 0.05 | AE13: 0
B14: Substation Physical Engineer | C14: =$C$2 -> Substation | D14: Engineering | E14: 0.05 | F14: 0.05 | G14: 0.05 | H14: 0.05 | I14: 0.05 | J14: 0.05 | K14: 0.1 | L14: 0.1 | M14: 0.1 | N14: 0.1 | O14: 0.1 | P14: 0.1 | Q14: 0.1 | R14: 0.1 | S14: 0.1 | T14: 0.1 | U14: 0.1 | V14: 0.1 | W14: 0.1 | X14: 0.1 | Y14: 0.1 | Z14: 0.1 | AA14: 0.1 | AB14: 0.1 | AC14: 0.05 | AD14: 0.05 | AE14: 0
B15: Mechanical Engineer | C15: =$C$2 -> Substation | D15: Engineering | E15: 0.05 | F15: 0.05 | G15: 0.05 | H15: 0.05 | I15: 0.05 | J15: 0.05 | K15: 0.1 | L15: 0.1 | M15: 0.1 | N15: 0.1 | O15: 0.1 | P15: 0.1 | Q15: 0.1 | R15: 0.1 | S15: 0.1 | T15: 0.1 | U15: 0.1 | V15: 0.1 | W15: 0.1 | X15: 0.1 | Y15: 0.1 | Z15: 0.1 | AA15: 0.1 | AB15: 0.1 | AC15: 0.05 | AD15: 0.05 | AE15: 0
B16: Substation P&C Detailed Engineer | C16: =$C$2 -> Substation | D16: Engineering | E16: 0.05 | F16: 0.05 | G16: 0.05 | H16: 0.05 | I16: 0.05 | J16: 0.05 | K16: 0.1 | L16: 0.1 | M16: 0.1 | N16: 0.1 | O16: 0.1 | P16: 0.1 | Q16: 0.1 | R16: 0.1 | S16: 0.1 | T16: 0.1 | U16: 0.1 | V16: 0.1 | W16: 0.1 | X16: 0.1 | Y16: 0.1 | Z16: 0.1 | AA16: 0.1 | AB16: 0.1 | AC16: 0.05 | AD16: 0.05 | AE16: 0
B17: Construction Manager | C17: =$C$2 -> Substation | D17: Construction Monitoring | E17: 0 | F17: 0 | G17: 0 | H17: 0.25 | I17: 0.25 | J17: 0.25 | K17: 0.5 | L17: 0.5 | M17: 0.5 | N17: 0.75 | O17: 0.75 | P17: 0.75 | Q17: 0.75 | R17: 0.75 | S17: 0.75 | T17: 0.75 | U17: 0.75 | V17: 0.75 | W17: 0.75 | X17: 0.75 | Y17: 0.75 | Z17: 0.75 | AA17: 0.75 | AB17: 0.75 | AC17: 0.5 | AD17: 0.4 | AE17: 0.25
... B23: Cost Controls | C23: =$C$2 -> Substation | D23: Project Controls | E23: 0.2 | F23: 0.2 | G23: 0.2 | H23: 0.2 | I23: 0.2 | J23: 0.2 | K23: 0.45 | L23: 0.45 | M23: 0.45 | N23: 0.45 | O23: 0.45 | P23: 0.45 | Q23: 0.45 | R23: 0.45 | S23: 0.45 | T23: 0.45 | U23: 0.45 | V23: 0.45 | W23: 0.45 | X23: 0.45 | Y23: 0.45 | Z23: 0.45 | AA23: 0.45 | AB23: 0.45 | AC23: 0.15 | AD23: 0.15 | AE23: 0.15

Sheet Thermal
B2: PROJECT ARCHETYPE: | C2: Thermal
B4: Resource Name | C4: Project Archetype | D4: Resource Category | E4: Planning | K4: Design & Engineering | Q4: Construction | AC4: Closeout
B5: Column1 | C5: Column2 | D5: Column3 | E5: 1 | F5: 2 | G5: 3 | H5: 4 | I5: 5 | J5: 6 | K5: 7 | L5: 8 | M5: 9 | N5: 10 | O5: 11 | P5: 12 | Q5: 13 | R5: 14 | S5: 15 | T5: 16 | U5: 17 | V5: 18 | W5: 19 | X5: 20 | Y5: 21 | Z5: 22 | AA5: 23 | AB5: 24 | AC5: 25 | AD5: 26 | AE5: 27
B6: Project Manager | C6: =$C$2 -> Thermal | D6: Project Management | E6: 0.25 | F6: 0.25 | G6: 0.25 | H6: 0.45 | I6: 0.45 | J6: 0.45 | K6: 0.65 | L6: 0.65 | M6: 0.65 | N6: 0.85 | O6: 0.85 | P6: 0.85 | Q6: 0.85 | R6: 0.85 | S6: 0.85 | T6: 0.85 | U6: 0.85 | V6: 0.85 | W6: 0.85 | X6: 0.85 | Y6: 0.85 | Z6: 0.85 | AA6: 0.85 | AB6: 0.85 | AC6: 0.5 | AD6: 0.4 | AE6: 0.25
B7: Project Engineer | C7: =$C$2 -> Thermal | D7: Project Management | E7: 0.05 | F7: 0.05 | G7: 0.05 | H7: 0.05 | I7: 0.05 | J7: 0.05 | K7: 0.05 | L7: 0.05 | M7: 0.05 | N7: 0.05 | O7: 0.05 | P7: 0.05 | Q7: 0.05 | R7: 0.05 | S7: 0.05 | T7: 0.05 | U7: 0.05 | V7: 0.05 | W7: 0.05 | X7: 0.05 | Y7: 0.05 | Z7: 0.05 | AA7: 0.05 | AB7: 0.05 | AC7: 0.05 | AD7: 0.05 | AE7: 0.05
B8: Project Coordinator | C8: =$C$2 -> Thermal | D8: Project Management | E8: 0.05 | F8: 0.05 | G8: 0.1 | H8: 0.1 | I8: 0.15 | J8: 0.15 | K8: 0.25 | L8: 0.25 | M8: 0.25 | N8: 0.25 | O8: 0.25 | P8: 0.25 | Q8: 0.25 | R8: 0.25 | S8: 0.25 | T8: 0.25 | U8: 0.25 | V8: 0.25 | W8: 0.25 | X8: 0.25 | Y8: 0.25 | Z8: 0.25 | AA8: 0.25 | AB8: 0.25 | AC8: 0.25 | AD8: 0.25 | AE8: 0.25
B9: Civil Engineer | C9: =$C$2 -> Thermal | D9: Engineering | E9: 0.05 | F9: 0.05 | G9: 0.05 | H9: 0.05 | I9: 0.05 | J9: 0.05 | K9: 0.1 | L9: 0.1 | M9: 0.1 | N9: 0.1 | O9: 0.1 | P9: 0.1 | Q9: 0.1 | R9: 0.1 | S9: 0.1 | T9: 0.1 | U9: 0.1 | V9: 0.1 | W9: 0.1 | X9: 0.1 | Y9: 0.1 | Z9: 0.1 | AA9: 0.1 | AB9: 0.1 | AC9: 0.05 | AD9: 0.05 | AE9: 0
B10: I&C Engineer | C10: =$C$2 -> Thermal | D10: Engineering | E10: 0.05 | F10: 0.05 | G10: 0.05 | H10: 0.05 | I10: 0.05 | J10: 0.05 | K10: 0.1 | L10: 0.1 | M10: 0.1 | N10: 0.1 | O10: 0.1 | P10: 0.1 | Q10: 0.1 | R10: 0.1 | S10: 0.1 | T10: 0.1 | U10: 0.1 | V10: 0.1 | W10: 0.1 | X10: 0.1 | Y10: 0.1 | Z10: 0.1 | AA10: 0.1 | AB10: 0.1 | AC10: 0.05 | AD10: 0.05 | AE10: 0
B11: Electrical Engineer | C11: =$C$2 -> Thermal | D11: Engineering | E11: 0.05 | F11: 0.05 | G11: 0.05 | H11: 0.05 | I11: 0.05 | J11: 0.05 | K11: 0.1 | L11: 0.1 | M11: 0.1 | N11: 0.1 | O11: 0.1 | P11: 0.1 | Q11: 0.1 | R11: 0.1 | S11: 0.1 | T11: 0.1 | U11: 0.1 | V11: 0.1 | W11: 0.1 | X11: 0.1 | Y11: 0.1 | Z11: 0.1 | AA11: 0.1 | AB11: 0.1 | AC11: 0.05 | AD11: 0.05 | AE11: 0
B12: Mechanical Engineer | C12: =$C$2 -> Thermal | D12: Engineering | E12: 0.05 | F12: 0.05 | G12: 0.05 | H12: 0.05 | I12: 0.05 | J12: 0.05 | K12: 0.1 | L12: 0.1 | M12: 0.1 | N12: 0.1 | O12: 0.1 | P12: 0.1 | Q12: 0.1 | R12: 0.1 | S12: 0.1 | T12: 0.1 | U12: 0.1 | V12: 0.1 | W12: 0.1 | X12: 0.1 | Y12: 0.1 | Z12: 0.1 | AA12: 0.1 | AB12: 0.1 | AC12: 0.05 | AD12: 0.05 | AE12: 0
B13: Structural Engineer | C13: =$C$2 -> Thermal | D13: Engineering | E13: 0.05 | F13: 0.05 | G13: 0.05 | H13: 0.05 | I13: 0.05 | J13: 0.05 | K13: 0.1 | L13: 0.1 | M13: 0.1 | N13: 0.1 | O13: 0.1 | P13: 0.1 | Q13: 0.1 | R13: 0.1 | S13: 0.1 | T13: 0.1 | U13: 0.1 | V13: 0.1 | W13: 0.1 | X13: 0.1 | Y13: 0.1 | Z13: 0.1 | AA13: 0.1 | AB13: 0.1 | AC13: 0.05 | AD13: 0.05 | AE13: 0
B14: Construction Manager | C14: =$C$2 -> Thermal | D14: Construction Monitoring | E14: 0 | F14: 0 | G14: 0 | H14: 0.25 | I14: 0.25 | J14: 0.25 | K14: 0.5 | L14: 0.5 | M14: 0.5 | N14: 0.75 | O14: 0.75 | P14: 0.75 | Q14: 0.75 | R14: 0.75 | S14: 0.75 | T14: 0.75 | U14: 0.75 | V14: 0.75 | W14: 0.75 | X14: 0.75 | Y14: 0.75 | Z14: 0.75 | AA14: 0.75 | AB14: 0.75 | AC14: 0.5 | AD14: 0.4 | AE14: 0.25
B15: H&S Field | C15: =$C$2 -> Thermal | D15: Construction Monitoring | E15: 0 | F15: 0 | G15: 0 | H15: 0 | I15: 0 | J15: 0 | K15: 0 | L15: 0 | M15: 0 | N15: 0 | O15: 0 | P15: 0 | Q15: 0.5 | R15: 0.5 | S15: 0.5 | T15: 0.5 | U15: 0.5 | V15: 0.5 | W15: 0.5 | X15: 0.5 | Y15: 0.5 | Z15: 0.5 | AA15: 0.5 | AB15: 0.5 | AC15: 0.25 | AD15: 0.15 | AE15: 0
B16: Estimator | C16: =$C$2 -> Thermal | D16: Project Controls | E16: 0.1 | F16: 0.1 | G16: 0.1 | H16: 0.1 | I16: 0.1 | J16: 0.1 | K16: 0.1 | L16: 0.1 | M16: 0.1 | N16: 0.1 | O16: 0.1 | P16: 0.1 | Q16: 0.1 | R16: 0.1 | S16: 0.1 | T16: 0.1 | U16: 0.1 | V16: 0.1 | W16: 0.1 | X16: 0.1 | Y16: 0.1 | Z16: 0.1 | AA16: 0.1 | AB16: 0.1 | AC16: 0.1 | AD16: 0.1 | AE16: 0.1
B17: Risk Analyst | C17: =$C$2 -> Thermal | D17: Project Controls | E17: 0.05 | F17: 0.05 | G17: 0.05 | H17: 0.05 | I17: 0.05 | J17: 0.05 | K17: 0.05 | L17: 0.05 | M17: 0.05 | N17: 0.05 | O17: 0.05 | P17: 0.05 | Q17: 0.05 | R17: 0.05 | S17: 0.05 | T17: 0.05 | U17: 0.05 | V17: 0.05 | W17: 0.05 | X17: 0.05 | Y17: 0.05 | Z17: 0.05 | AA17: 0.05 | AB17: 0.05 | AC17: 0.05 | AD17: 0 | AE17: 0
... B20: Cost Controls | C20: =$C$2 -> Thermal | D20: Project Controls | E20: 0.1 | F20: 0.1 | G20: 0.1 | H20: 0.1 | I20: 0.1 | J20: 0.1 | K20: 0.1 | L20: 0.1 | M20: 0.1 | N20: 0.1 | O20: 0.1 | P20: 0.1 | Q20: 0.1 | R20: 0.1 | S20: 0.1 | T20: 0.1 | U20: 0.1 | V20: 0.1 | W20: 0.1 | X20: 0.1 | Y20: 0.1 | Z20: 0.1 | AA20: 0.1 | AB20: 0.1 | AC20: 0.1 | AD20: 0.1 | AE20: 0.1

Sheet Gas
B2: PROJECT ARCHETYPE: | C2: Gas
B4: Resource Name | C4: Project Archetype | D4: Resource Category | E4: Planning | K4: Design & Engineering | Q4: Construction | AC4: Closeout
B5: Column1 | C5: Column2 | D5: Column3 | E5: 1 | F5: 2 | G5: 3 | H5: 4 | I5: 5 | J5: 6 | K5: 7 | L5: 8 | M5: 9 | N5: 10 | O5: 11 | P5: 12 | Q5: 13 | R5: 14 | S5: 15 | T5: 16 | U5: 17 | V5: 18 | W5: 19 | X5: 20 | Y5: 21 | Z5: 22 | AA5: 23 | AB5: 24 | AC5: 25 | AD5: 26 | AE5: 27
B6: Project Manager | C6: =$C$2 -> Gas | D6: Project Management | E6: 0.25 | F6: 0.25 | G6: 0.25 | H6: 0.45 | I6: 0.45 | J6: 0.45 | K6: 0.65 | L6: 0.65 | M6: 0.65 | N6: 0.85 | O6: 0.85 | P6: 0.85 | Q6: 0.85 | R6: 0.85 | S6: 0.85 | T6: 0.85 | U6: 0.85 | V6: 0.85 | W6: 0.85 | X6: 0.85 | Y6: 0.85 | Z6: 0.85 | AA6: 0.85 | AB6: 0.85 | AC6: 0.5 | AD6: 0.4 | AE6: 0.25
B7: Project Engineer | C7: =$C$2 -> Gas | D7: Project Management | E7: 0.05 | F7: 0.05 | G7: 0.05 | H7: 0.05 | I7: 0.05 | J7: 0.05 | K7: 0.05 | L7: 0.05 | M7: 0.05 | N7: 0.05 | O7: 0.05 | P7: 0.05 | Q7: 0.05 | R7: 0.05 | S7: 0.05 | T7: 0.05 | U7: 0.05 | V7: 0.05 | W7: 0.05 | X7: 0.05 | Y7: 0.05 | Z7: 0.05 | AA7: 0.05 | AB7: 0.05 | AC7: 0.05 | AD7: 0.05 | AE7: 0.05
B8: Project Coordinator | C8: =$C$2 -> Gas | D8: Project Management | E8: 0.05 | F8: 0.05 | G8: 0.1 | H8: 0.1 | I8: 0.15 | J8: 0.15 | K8: 0.25 | L8: 0.25 | M8: 0.25 | N8: 0.25 | O8: 0.25 | P8: 0.25 | Q8: 0.25 | R8: 0.25 | S8: 0.25 | T8: 0.25 | U8: 0.25 | V8: 0.25 | W8: 0.25 | X8: 0.25 | Y8: 0.25 | Z8: 0.25 | AA8: 0.25 | AB8: 0.25 | AC8: 0.25 | AD8: 0.25 | AE8: 0.25
B9: Civil Engineer | C9: =$C$2 -> Gas | D9: Engineering | E9: 0.05 | F9: 0.05 | G9: 0.05 | H9: 0.05 | I9: 0.05 | J9: 0.05 | K9: 0.1 | L9: 0.1 | M9: 0.1 | N9: 0.1 | O9: 0.1 | P9: 0.1 | Q9: 0.1 | R9: 0.1 | S9: 0.1 | T9: 0.1 | U9: 0.1 | V9: 0.1 | W9: 0.1 | X9: 0.1 | Y9: 0.1 | Z9: 0.1 | AA9: 0.1 | AB9: 0.1 | AC9: 0.05 | AD9: 0.05 | AE9: 0
B10: Structural Engineer | C10: =$C$2 -> Gas | D10: Engineering | E10: 0.05 | F10: 0.05 | G10: 0.05 | H10: 0.05 | I10: 0.05 | J10: 0.05 | K10: 0.1 | L10: 0.1 | M10: 0.1 | N10: 0.1 | O10: 0.1 | P10: 0.1 | Q10: 0.1 | R10: 0.1 | S10: 0.1 | T10: 0.1 | U10: 0.1 | V10: 0.1 | W10: 0.1 | X10: 0.1 | Y10: 0.1 | Z10: 0.1 | AA10: 0.1 | AB10: 0.1 | AC10: 0.05 | AD10: 0.05 | AE10: 0
B11: Mechanical Engineer | C11: =$C$2 -> Gas | D11: Engineering | E11: 0.05 | F11: 0.05 | G11: 0.05 | H11: 0.05 | I11: 0.05 | J11: 0.05 | K11: 0.1 | L11: 0.1 | M11: 0.1 | N11: 0.1 | O11: 0.1 | P11: 0.1 | Q11: 0.1 | R11: 0.1 | S11: 0.1 | T11: 0.1 | U11: 0.1 | V11: 0.1 | W11: 0.1 | X11: 0.1 | Y11: 0.1 | Z11: 0.1 | AA11: 0.1 | AB11: 0.1 | AC11: 0.05 | AD11: 0.05 | AE11: 0
B12: Construction Manager | C12: =$C$2 -> Gas | D12: Construction Monitoring | E12: 0 | F12: 0 | G12: 0 | H12: 0.25 | I12: 0.25 | J12: 0.25 | K12: 0.5 | L12: 0.5 | M12: 0.5 | N12: 0.75 | O12: 0.75 | P12: 0.75 | Q12: 0.75 | R12: 0.75 | S12: 0.75 | T12: 0.75 | U12: 0.75 | V12: 0.75 | W12: 0.75 | X12: 0.75 | Y12: 0.75 | Z12: 0.75 | AA12: 0.75 | AB12: 0.75 | AC12: 0.5 | AD12: 0.4 | AE12: 0.25
B13: H&S Field | C13: =$C$2 -> Gas | D13: Construction Monitoring | E13: 0 | F13: 0 | G13: 0 | H13: 0 | I13: 0 | J13: 0 | K13: 0 | L13: 0 | M13: 0 | N13: 0 | O13: 0 | P13: 0 | Q13: 0.5 | R13: 0.5 | S13: 0.5 | T13: 0.5 | U13: 0.5 | V13: 0.5 | W13: 0.5 | X13: 0.5 | Y13: 0.5 | Z13: 0.5 | AA13: 0.5 | AB13: 0.5 | AC13: 0.25 | AD13: 0.15 | AE13: 0
B14: Estimator | C14: =$C$2 -> Gas | D14: Project Controls | E14: 0.1 | F14: 0.1 | G14: 0.1 | H14: 0.1 | I14: 0.1 | J14: 0.1 | K14: 0.15 | L14: 0.15 | M14: 0.15 | N14: 0.15 | O14: 0.15 | P14: 0.15 | Q14: 0.1 | R14: 0.1 | S14: 0.1 | T14: 0.1 | U14: 0.1 | V14: 0.1 | W14: 0.1 | X14: 0.1 | Y14: 0.1 | Z14: 0.1 | AA14: 0.1 | AB14: 0.1 | AC14: 0.05 | AD14: 0.05 | AE14: 0.05
B15: Risk Analyst | C15: =$C$2 -> Gas | D15: Project Controls | E15: 0.1 | F15: 0.1 | G15: 0.1 | H15: 0.1 | I15: 0.1 | J15: 0.1 | K15: 0.1 | L15: 0.1 | M15: 0.1 | N15: 0.1 | O15: 0.1 | P15: 0.1 | Q15: 0.1 | R15: 0.1 | S15: 0.1 | T15: 0.1 | U15: 0.1 | V15: 0.1 | W15: 0.1 | X15: 0.1 | Y15: 0.1 | Z15: 0.1 | AA15: 0.1 | AB15: 0.1 | AC15: 0.05 | AD15: 0.05 | AE15: 0.05
B16: Document Control Specialist | C16: =$C$2 -> Gas | D16: Project Controls | E16: 0.1 | F16: 0.1 | G16: 0.1 | H16: 0.1 | I16: 0.1 | J16: 0.1 | K16: 0.1 | L16: 0.1 | M16: 0.1 | N16: 0.1 | O16: 0.1 | P16: 0.1 | Q16: 0.2 | R16: 0.2 | S16: 0.2 | T16: 0.2 | U16: 0.2 | V16: 0.2 | W16: 0.2 | X16: 0.2 | Y16: 0.2 | Z16: 0.2 | AA16: 0.2 | AB16: 0.2 | AC16: 0.25 | AD16: 0.25 | AE16: 0.25
B17: Scheduler | C17: =$C$2 -> Gas | D17: Project Controls | E17: 0.2 | F17: 0.2 | G17: 0.2 | H17: 0.2 | I17: 0.2 | J17: 0.2 | K17: 0.2 | L17: 0.2 | M17: 0.2 | N17: 0.2 | O17: 0.2 | P17: 0.2 | Q17: 0.2 | R17: 0.2 | S17: 0.2 | T17: 0.2 | U17: 0.2 | V17: 0.2 | W17: 0.2 | X17: 0.2 | Y17: 0.2 | Z17: 0.2 | AA17: 0.2 | AB17: 0.2 | AC17: 0.05 | AD17: 0.05 | AE17: 0.05
B18: Cost Controls | C18: =$C$2 -> Gas | D18: Project Controls | E18: 0.2 | F18: 0.2 | G18: 0.2 | H18: 0.2 | I18: 0.2 | J18: 0.2 | K18: 0.45 | L18: 0.45 | M18: 0.45 | N18: 0.45 | O18: 0.45 | P18: 0.45 | Q18: 0.45 | R18: 0.45 | S18: 0.45 | T18: 0.45 | U18: 0.45 | V18: 0.45 | W18: 0.45 | X18: 0.45 | Y18: 0.45 | Z18: 0.45 | AA18: 0.45 | AB18: 0.45 | AC18: 0.15 | AD18: 0.15 | AE18: 0.15

Sheet Wind
B2: PROJECT ARCHETYPE: | C2: Wind
B4: Resource Name | C4: Project Archetype | D4: Resource Category | E4: Planning | K4: Design & Engineering | Q4: Construction | AC4: Closeout
B5: Column1 | C5: Column2 | D5: Column3 | E5: 1 | F5: 2 | G5: 3 | H5: 4 | I5: 5 | J5: 6 | K5: 7 | L5: 8 | M5: 9 | N5: 10 | O5: 11 | P5: 12 | Q5: 13 | R5: 14 | S5: 15 | T5: 16 | U5: 17 | V5: 18 | W5: 19 | X5: 20 | Y5: 21 | Z5: 22 | AA5: 23 | AB5: 24 | AC5: 25 | AD5: 26 | AE5: 27
B6: Project Manager | C6: =$C$2 -> Wind | D6: Project Management | E6: 0.25 | F6: 0.25 | G6: 0.25 | H6: 0.45 | I6: 0.45 | J6: 0.45 | K6: 0.65 | L6: 0.65 | M6: 0.65 | N6: 0.85 | O6: 0.85 | P6: 0.85 | Q6: 0.85 | R6: 0.85 | S6: 0.85 | T6: 0.85 | U6: 0.85 | V6: 0.85 | W6: 0.85 | X6: 0.85 | Y6: 0.85 | Z6: 0.85 | AA6: 0.85 | AB6: 0.85 | AC6: 0.5 | AD6: 0.4 | AE6: 0.25
B7: Project Engineer | C7: =$C$2 -> Wind | D7: Project Management | E7: 0.05 | F7: 0.05 | G7: 0.05 | H7: 0.05 | I7: 0.05 | J7: 0.05 | K7: 0.05 | L7: 0.05 | M7: 0.05 | N7: 0.05 | O7: 0.05 | P7: 0.05 | Q7: 0.05 | R7: 0.05 | S7: 0.05 | T7: 0.05 | U7: 0.05 | V7: 0.05 | W7: 0.05 | X7: 0.05 | Y7: 0.05 | Z7: 0.05 | AA7: 0.05 | AB7: 0.05 | AC7: 0.05 | AD7: 0.05 | AE7: 0.05
B8: Project Coordinator | C8: =$C$2 -> Wind | D8: Project Management | E8: 0.05 | F8: 0.05 | G8: 0.1 | H8: 0.1 | I8: 0.15 | J8: 0.15 | K8: 0.25 | L8: 0.25 | M8: 0.25 | N8: 0.25 | O8: 0.25 | P8: 0.25 | Q8: 0.25 | R8: 0.25 | S8: 0.25 | T8: 0.25 | U8: 0.25 | V8: 0.25 | W8: 0.25 | X8: 0.25 | Y8: 0.25 | Z8: 0.25 | AA8: 0.25 | AB8: 0.25 | AC8: 0.25 | AD8: 0.25 | AE8: 0.25
B9: Civil Engineer | C9: =$C$2 -> Wind | D9: Engineering | E9: 0.05 | F9: 0.05 | G9: 0.05 | H9: 0.05 | I9: 0.05 | J9: 0.05 | K9: 0.1 | L9: 0.1 | M9: 0.1 | N9: 0.1 | O9: 0.1 | P9: 0.1 | Q9: 0.1 | R9: 0.1 | S9: 0.1 | T9: 0.1 | U9: 0.1 | V9: 0.1 | W9: 0.1 | X9: 0.1 | Y9: 0.1 | Z9: 0.1 | AA9: 0.1 | AB9: 0.1 | AC9: 0.05 | AD9: 0.05 | AE9: 0
B10: I&C Engineer | C10: =$C$2 -> Wind | D10: Engineering | E10: 0.05 | F10: 0.05 | G10: 0.05 | H10: 0.05 | I10: 0.05 | J10: 0.05 | K10: 0.1 | L10: 0.1 | M10: 0.1 | N10: 0.1 | O10: 0.1 | P10: 0.1 | Q10: 0.1 | R10: 0.1 | S10: 0.1 | T10: 0.1 | U10: 0.1 | V10: 0.1 | W10: 0.1 | X10: 0.1 | Y10: 0.1 | Z10: 0.1 | AA10: 0.1 | AB10: 0.1 | AC10: 0.05 | AD10: 0.05 | AE10: 0
B11: Electrical Engineer | C11: =$C$2 -> Wind | D11: Engineering | E11: 0.05 | F11: 0.05 | G11: 0.05 | H11: 0.05 | I11: 0.05 | J11: 0.05 | K11: 0.1 | L11: 0.1 | M11: 0.1 | N11: 0.1 | O11: 0.1 | P11: 0.1 | Q11: 0.1 | R11: 0.1 | S11: 0.1 | T11: 0.1 | U11: 0.1 | V11: 0.1 | W11: 0.1 | X11: 0.1 | Y11: 0.1 | Z11: 0.1 | AA11: 0.1 | AB11: 0.1 | AC11: 0.05 | AD11: 0.05 | AE11: 0
B12: Mechanical Engineer | C12: =$C$2 -> Wind | D12: Engineering | E12: 0.05 | F12: 0.05 | G12: 0.05 | H12: 0.05 | I12: 0.05 | J12: 0.05 | K12: 0.1 | L12: 0.1 | M12: 0.1 | N12: 0.1 | O12: 0.1 | P12: 0.1 | Q12: 0.1 | R12: 0.1 | S12: 0.1 | T12: 0.1 | U12: 0.1 | V12: 0.1 | W12: 0.1 | X12: 0.1 | Y12: 0.1 | Z12: 0.1 | AA12: 0.1 | AB12: 0.1 | AC12: 0.05 | AD12: 0.05 | AE12: 0
B13: Structural Engineer | C13: =$C$2 -> Wind | D13: Engineering | E13: 0.05 | F13: 0.05 | G13: 0.05 | H13: 0.05 | I13: 0.05 | J13: 0.05 | K13: 0.1 | L13: 0.1 | M13: 0.1 | N13: 0.1 | O13: 0.1 | P13: 0.1 | Q13: 0.1 | R13: 0.1 | S13: 0.1 | T13: 0.1 | U13: 0.1 | V13: 0.1 | W13: 0.1 | X13: 0.1 | Y13: 0.1 | Z13: 0.1 | AA13: 0.1 | AB13: 0.1 | AC13: 0.05 | AD13: 0.05 | AE13: 0
B14: Construction Manager | C14: =$C$2 -> Wind | D14: Construction Monitoring | E14: 0 | F14: 0 | G14: 0 | H14: 0.25 | I14: 0.25 | J14: 0.25 | K14: 0.5 | L14: 0.5 | M14: 0.5 | N14: 0.75 | O14: 0.75 | P14: 0.75 | Q14: 0.75 | R14: 0.75 | S14: 0.75 | T14: 0.75 | U14: 0.75 | V14: 0.75 | W14: 0.75 | X14: 0.75 | Y14: 0.75 | Z14: 0.75 | AA14: 0.75 | AB14: 0.75 | AC14: 0.5 | AD14: 0.4 | AE14: 0.25
B15: H&S Field | C15: =$C$2 -> Wind | D15: Construction Monitoring | E15: 0 | F15: 0 | G15: 0 | H15: 0 | I15: 0 | J15: 0 | K15: 0 | L15: 0 | M15: 0 | N15: 0 | O15: 0 | P15: 0 | Q15: 0.5 | R15: 0.5 | S15: 0.5 | T15: 0.5 | U15: 0.5 | V15: 0.5 | W15: 0.5 | X15: 0.5 | Y15: 0.5 | Z15: 0.5 | AA15: 0.5 | AB15: 0.5 | AC15: 0.25 | AD15: 0.15 | AE15: 0
B16: Estimator | C16: =$C$2 -> Wind | D16: Project Controls | E16: 0.1 | F16: 0.1 | G16: 0.1 | H16: 0.1 | I16: 0.1 | J16: 0.1 | K16: 0.1 | L16: 0.1 | M16: 0.1 | N16: 0.1 | O16: 0.1 | P16: 0.1 | Q16: 0.1 | R16: 0.1 | S16: 0.1 | T16: 0.1 | U16: 0.1 | V16: 0.1 | W16: 0.1 | X16: 0.1 | Y16: 0.1 | Z16: 0.1 | AA16: 0.1 | AB16: 0.1 | AC16: 0.1 | AD16: 0.1 | AE16: 0.1
B17: Risk Analyst | C17: =$C$2 -> Wind | D17: Project Controls | E17: 0.05 | F17: 0.05 | G17: 0.05 | H17: 0.05 | I17: 0.05 | J17: 0.05 | K17: 0.05 | L17: 0.05 | M17: 0.05 | N17: 0.05 | O17: 0.05 | P17: 0.05 | Q17: 0.05 | R17: 0.05 | S17: 0.05 | T17: 0.05 | U17: 0.05 | V17: 0.05 | W17: 0.05 | X17: 0.05 | Y17: 0.05 | Z17: 0.05 | AA17: 0.05 | AB17: 0.05 | AC17: 0.05 | AD17: 0 | AE17: 0
... B20: Cost Controls | C20: =$C$2 -> Wind | D20: Project Controls | E20: 0.1 | F20: 0.1 | G20: 0.1 | H20: 0.1 | I20: 0.1 | J20: 0.1 | K20: 0.1 | L20: 0.1 | M20: 0.1 | N20: 0.1 | O20: 0.1 | P20: 0.1 | Q20: 0.1 | R20: 0.1 | S20: 0.1 | T20: 0.1 | U20: 0.1 | V20: 0.1 | W20: 0.1 | X20: 0.1 | Y20: 0.1 | Z20: 0.1 | AA20: 0.1 | AB20: 0.1 | AC20: 0.1 | AD20: 0.1 | AE20: 0.1

Sheet Hydro
B2: PROJECT ARCHETYPE: | C2: Hydro
B4: Resource Name | C4: Project Archetype | D4: Resource Category | E4: Planning | K4: Design & Engineering | Q4: Construction | AC4: Closeout
B5: Column1 | C5: Column2 | D5: Column3 | E5: 1 | F5: 2 | G5: 3 | H5: 4 | I5: 5 | J5: 6 | K5: 7 | L5: 8 | M5: 9 | N5: 10 | O5: 11 | P5: 12 | Q5: 13 | R5: 14 | S5: 15 | T5: 16 | U5: 17 | V5: 18 | W5: 19 | X5: 20 | Y5: 21 | Z5: 22 | AA5: 23 | AB5: 24 | AC5: 25 | AD5: 26 | AE5: 27
B6: Project Manager | C6: =$C$2 -> Hydro | D6: Project Management | E6: 0.25 | F6: 0.25 | G6: 0.25 | H6: 0.45 | I6: 0.45 | J6: 0.45 | K6: 0.65 | L6: 0.65 | M6: 0.65 | N6: 0.85 | O6: 0.85 | P6: 0.85 | Q6: 0.85 | R6: 0.85 | S6: 0.85 | T6: 0.85 | U6: 0.85 | V6: 0.85 | W6: 0.85 | X6: 0.85 | Y6: 0.85 | Z6: 0.85 | AA6: 0.85 | AB6: 0.85 | AC6: 0.5 | AD6: 0.4 | AE6: 0.25
B7: Project Engineer | C7: =$C$2 -> Hydro | D7: Project Management | E7: 0.05 | F7: 0.05 | G7: 0.05 | H7: 0.05 | I7: 0.05 | J7: 0.05 | K7: 0.05 | L7: 0.05 | M7: 0.05 | N7: 0.05 | O7: 0.05 | P7: 0.05 | Q7: 0.05 | R7: 0.05 | S7: 0.05 | T7: 0.05 | U7: 0.05 | V7: 0.05 | W7: 0.05 | X7: 0.05 | Y7: 0.05 | Z7: 0.05 | AA7: 0.05 | AB7: 0.05 | AC7: 0.05 | AD7: 0.05 | AE7: 0.05
B8: Project Coordinator | C8: =$C$2 -> Hydro | D8: Project Management | E8: 0.05 | F8: 0.05 | G8: 0.1 | H8: 0.1 | I8: 0.15 | J8: 0.15 | K8: 0.25 | L8: 0.25 | M8: 0.25 | N8: 0.25 | O8: 0.25 | P8: 0.25 | Q8: 0.25 | R8: 0.25 | S8: 0.25 | T8: 0.25 | U8: 0.25 | V8: 0.25 | W8: 0.25 | X8: 0.25 | Y8: 0.25 | Z8: 0.25 | AA8: 0.25 | AB8: 0.25 | AC8: 0.25 | AD8: 0.25 | AE8: 0.25
B9: Geotech Engineer | C9: =$C$2 -> Hydro | D9: Engineering | E9: 0.05 | F9: 0.05 | G9: 0.05 | H9: 0.05 | I9: 0.05 | J9: 0.05 | K9: 0.1 | L9: 0.1 | M9: 0.1 | N9: 0.1 | O9: 0.1 | P9: 0.1 | Q9: 0.1 | R9: 0.1 | S9: 0.1 | T9: 0.1 | U9: 0.1 | V9: 0.1 | W9: 0.1 | X9: 0.1 | Y9: 0.1 | Z9: 0.1 | AA9: 0.1 | AB9: 0.1 | AC9: 0.05 | AD9: 0.05 | AE9: 0
B10: Civil Engineer | C10: =$C$2 -> Hydro | D10: Engineering | E10: 0.05 | F10: 0.05 | G10: 0.05 | H10: 0.05 | I10: 0.05 | J10: 0.05 | K10: 0.1 | L10: 0.1 | M10: 0.1 | N10: 0.1 | O10: 0.1 | P10: 0.1 | Q10: 0.1 | R10: 0.1 | S10: 0.1 | T10: 0.1 | U10: 0.1 | V10: 0.1 | W10: 0.1 | X10: 0.1 | Y10: 0.1 | Z10: 0.1 | AA10: 0.1 | AB10: 0.1 | AC10: 0.05 | AD10: 0.05 | AE10: 0
B11: Hydraulics/Hydrology Engineer | C11: =$C$2 -> Hydro | D11: Engineering | E11: 0.05 | F11: 0.05 | G11: 0.05 | H11: 0.05 | I11: 0.05 | J11: 0.05 | K11: 0.1 | L11: 0.1 | M11: 0.1 | N11: 0.1 | O11: 0.1 | P11: 0.1 | Q11: 0.1 | R11: 0.1 | S11: 0.1 | T11: 0.1 | U11: 0.1 | V11: 0.1 | W11: 0.1 | X11: 0.1 | Y11: 0.1 | Z11: 0.1 | AA11: 0.1 | AB11: 0.1 | AC11: 0.05 | AD11: 0.05 | AE11: 0
B12: I&C Engineer | C12: =$C$2 -> Hydro | D12: Engineering | E12: 0.05 | F12: 0.05 | G12: 0.05 | H12: 0.05 | I12: 0.05 | J12: 0.05 | K12: 0.1 | L12: 0.1 | M12: 0.1 | N12: 0.1 | O12: 0.1 | P12: 0.1 | Q12: 0.1 | R12: 0.1 | S12: 0.1 | T12: 0.1 | U12: 0.1 | V12: 0.1 | W12: 0.1 | X12: 0.1 | Y12: 0.1 | Z12: 0.1 | AA12: 0.1 | AB12: 0.1 | AC12: 0.05 | AD12: 0.05 | AE12: 0
B13: Electrical Engineer | C13: =$C$2 -> Hydro | D13: Engineering | E13: 0.05 | F13: 0.05 | G13: 0.05 | H13: 0.05 | I13: 0.05 | J13: 0.05 | K13: 0.1 | L13: 0.1 | M13: 0.1 | N13: 0.1 | O13: 0.1 | P13: 0.1 | Q13: 0.1 | R13: 0.1 | S13: 0.1 | T13: 0.1 | U13: 0.1 | V13: 0.1 | W13: 0.1 | X13: 0.1 | Y13: 0.1 | Z13: 0.1 | AA13: 0.1 | AB13: 0.1 | AC13: 0.05 | AD13: 0.05 | AE13: 0
B14: Mechanical Engineer | C14: =$C$2 -> Hydro | D14: Engineering | E14: 0.05 | F14: 0.05 | G14: 0.05 | H14: 0.05 | I14: 0.05 | J14: 0.05 | K14: 0.1 | L14: 0.1 | M14: 0.1 | N14: 0.1 | O14: 0.1 | P14: 0.1 | Q14: 0.1 | R14: 0.1 | S14: 0.1 | T14: 0.1 | U14: 0.1 | V14: 0.1 | W14: 0.1 | X14: 0.1 | Y14: 0.1 | Z14: 0.1 | AA14: 0.1 | AB14: 0.1 | AC14: 0.05 | AD14: 0.05 | AE14: 0
B15: Structural Engineer | C15: =$C$2 -> Hydro | D15: Engineering | E15: 0.05 | F15: 0.05 | G15: 0.05 | H15: 0.05 | I15: 0.05 | J15: 0.05 | K15: 0.1 | L15: 0.1 | M15: 0.1 | N15: 0.1 | O15: 0.1 | P15: 0.1 | Q15: 0.1 | R15: 0.1 | S15: 0.1 | T15: 0.1 | U15: 0.1 | V15: 0.1 | W15: 0.1 | X15: 0.1 | Y15: 0.1 | Z15: 0.1 | AA15: 0.1 | AB15: 0.1 | AC15: 0.05 | AD15: 0.05 | AE15: 0
B16: Construction Manager | C16: =$C$2 -> Hydro | D16: Construction Monitoring | E16: 0 | F16: 0 | G16: 0 | H16: 0.25 | I16: 0.25 | J16: 0.25 | K16: 0.5 | L16: 0.5 | M16: 0.5 | N16: 0.75 | O16: 0.75 | P16: 0.75 | Q16: 0.75 | R16: 0.75 | S16: 0.75 | T16: 0.75 | U16: 0.75 | V16: 0.75 | W16: 0.75 | X16: 0.75 | Y16: 0.75 | Z16: 0.75 | AA16: 0.75 | AB16: 0.75 | AC16: 0.5 | AD16: 0.4 | AE16: 0.25
B17: H&S Field | C17: =$C$2 -> Hydro | D17: Construction Monitoring | E17: 0 | F17: 0 | G17: 0 | H17: 0 | I17: 0 | J17: 0 | K17: 0 | L17: 0 | M17: 0 | N17: 0 | O17: 0 | P17: 0 | Q17: 0.5 | R17: 0.5 | S17: 0.5 | T17: 0.5 | U17: 0.5 | V17: 0.5 | W17: 0.5 | X17: 0.5 | Y17: 0.5 | Z17: 0.5 | AA17: 0.5 | AB17: 0.5 | AC17: 0.25 | AD17: 0.15 | AE17: 0
... B22: Cost Controls | C22: =$C$2 -> Hydro | D22: Project Controls | E22: 0.1 | F22: 0.1 | G22: 0.1 | H22: 0.1 | I22: 0.1 | J22: 0.1 | K22: 0.1 | L22: 0.1 | M22: 0.1 | N22: 0.1 | O22: 0.1 | P22: 0.1 | Q22: 0.1 | R22: 0.1 | S22: 0.1 | T22: 0.1 | U22: 0.1 | V22: 0.1 | W22: 0.1 | X22: 0.1 | Y22: 0.1 | Z22: 0.1 | AA22: 0.1 | AB22: 0.1 | AC22: 0.1 | AD22: 0.1 | AE22: 0.1

Sheet Biomass
B2: PROJECT ARCHETYPE: | C2: Biomass
B4: Resource Name | C4: Project Archetype | D4: Resource Category | E4: Planning | K4: Design & Engineering | Q4: Construction | AC4: Closeout
B5: Column1 | C5: Column2 | D5: Column3 | E5: 1 | F5: 2 | G5: 3 | H5: 4 | I5: 5 | J5: 6 | K5: 7 | L5: 8 | M5: 9 | N5: 10 | O5: 11 | P5: 12 | Q5: 13 | R5: 14 | S5: 15 | T5: 16 | U5: 17 | V5: 18 | W5: 19 | X5: 20 | Y5: 21 | Z5: 22 | AA5: 23 | AB5: 24 | AC5: 25 | AD5: 26 | AE5: 27
B6: Project Manager | C6: =$C$2 -> Biomass | D6: Project Management | E6: 0.25 | F6: 0.25 | G6: 0.25 | H6: 0.45 | I6: 0.45 | J6: 0.45 | K6: 0.65 | L6: 0.65 | M6: 0.65 | N6: 0.85 | O6: 0.85 | P6: 0.85 | Q6: 0.85 | R6: 0.85 | S6: 0.85 | T6: 0.85 | U6: 0.85 | V6: 0.85 | W6: 0.85 | X6: 0.85 | Y6: 0.85 | Z6: 0.85 | AA6: 0.85 | AB6: 0.85 | AC6: 0.5 | AD6: 0.4 | AE6: 0.25
B7: Project Engineer | C7: =$C$2 -> Biomass | D7: Project Management | E7: 0.05 | F7: 0.05 | G7: 0.05 | H7: 0.05 | I7: 0.05 | J7: 0.05 | K7: 0.05 | L7: 0.05 | M7: 0.05 | N7: 0.05 | O7: 0.05 | P7: 0.05 | Q7: 0.05 | R7: 0.05 | S7: 0.05 | T7: 0.05 | U7: 0.05 | V7: 0.05 | W7: 0.05 | X7: 0.05 | Y7: 0.05 | Z7: 0.05 | AA7: 0.05 | AB7: 0.05 | AC7: 0.05 | AD7: 0.05 | AE7: 0.05
B8: Project Coordinator | C8: =$C$2 -> Biomass | D8: Project Management | E8: 0.05 | F8: 0.05 | G8: 0.1 | H8: 0.1 | I8: 0.15 | J8: 0.15 | K8: 0.25 | L8: 0.25 | M8: 0.25 | N8: 0.25 | O8: 0.25 | P8: 0.25 | Q8: 0.25 | R8: 0.25 | S8: 0.25 | T8: 0.25 | U8: 0.25 | V8: 0.25 | W8: 0.25 | X8: 0.25 | Y8: 0.25 | Z8: 0.25 | AA8: 0.25 | AB8: 0.25 | AC8: 0.25 | AD8: 0.25 | AE8: 0.25
B9: Civil Engineer | C9: =$C$2 -> Biomass | D9: Engineering | E9: 0.05 | F9: 0.05 | G9: 0.05 | H9: 0.05 | I9: 0.05 | J9: 0.05 | K9: 0.1 | L9: 0.1 | M9: 0.1 | N9: 0.1 | O9: 0.1 | P9: 0.1 | Q9: 0.1 | R9: 0.1 | S9: 0.1 | T9: 0.1 | U9: 0.1 | V9: 0.1 | W9: 0.1 | X9: 0.1 | Y9: 0.1 | Z9: 0.1 | AA9: 0.1 | AB9: 0.1 | AC9: 0.05 | AD9: 0.05 | AE9: 0
B10: Structural Engineer | C10: =$C$2 -> Biomass | D10: Engineering | E10: 0.05 | F10: 0.05 | G10: 0.05 | H10: 0.05 | I10: 0.05 | J10: 0.05 | K10: 0.1 | L10: 0.1 | M10: 0.1 | N10: 0.1 | O10: 0.1 | P10: 0.1 | Q10: 0.1 | R10: 0.1 | S10: 0.1 | T10: 0.1 | U10: 0.1 | V10: 0.1 | W10: 0.1 | X10: 0.1 | Y10: 0.1 | Z10: 0.1 | AA10: 0.1 | AB10: 0.1 | AC10: 0.05 | AD10: 0.05 | AE10: 0
B11: Mechanical Engineer | C11: =$C$2 -> Biomass | D11: Engineering | E11: 0.05 | F11: 0.05 | G11: 0.05 | H11: 0.05 | I11: 0.05 | J11: 0.05 | K11: 0.1 | L11: 0.1 | M11: 0.1 | N11: 0.1 | O11: 0.1 | P11: 0.1 | Q11: 0.1 | R11: 0.1 | S11: 0.1 | T11: 0.1 | U11: 0.1 | V11: 0.1 | W11: 0.1 | X11: 0.1 | Y11: 0.1 | Z11: 0.1 | AA11: 0.1 | AB11: 0.1 | AC11: 0.05 | AD11: 0.05 | AE11: 0
B12: Construction Manager | C12: =$C$2 -> Biomass | D12: Construction Monitoring | E12: 0 | F12: 0 | G12: 0 | H12: 0.25 | I12: 0.25 | J12: 0.25 | K12: 0.5 | L12: 0.5 | M12: 0.5 | N12: 0.75 | O12: 0.75 | P12: 0.75 | Q12: 0.75 | R12: 0.75 | S12: 0.75 | T12: 0.75 | U12: 0.75 | V12: 0.75 | W12: 0.75 | X12: 0.75 | Y12: 0.75 | Z12: 0.75 | AA12: 0.75 | AB12: 0.75 | AC12: 0.5 | AD12: 0.4 | AE12: 0.25
B13: H&S Field | C13: =$C$2 -> Biomass | D13: Construction Monitoring | E13: 0 | F13: 0 | G13: 0 | H13: 0 | I13: 0 | J13: 0 | K13: 0 | L13: 0 | M13: 0 | N13: 0 | O13: 0 | P13: 0 | Q13: 0.5 | R13: 0.5 | S13: 0.5 | T13: 0.5 | U13: 0.5 | V13: 0.5 | W13: 0.5 | X13: 0.5 | Y13: 0.5 | Z13: 0.5 | AA13: 0.5 | AB13: 0.5 | AC13: 0.25 | AD13: 0.15 | AE13: 0
B14: Estimator | C14: =$C$2 -> Biomass | D14: Project Controls | E14: 0.1 | F14: 0.1 | G14: 0.1 | H14: 0.1 | I14: 0.1 | J14: 0.1 | K14: 0.1 | L14: 0.1 | M14: 0.1 | N14: 0.1 | O14: 0.1 | P14: 0.1 | Q14: 0.1 | R14: 0.1 | S14: 0.1 | T14: 0.1 | U14: 0.1 | V14: 0.1 | W14: 0.1 | X14: 0.1 | Y14: 0.1 | Z14: 0.1 | AA14: 0.1 | AB14: 0.1 | AC14: 0.1 | AD14: 0.1 | AE14: 0.1
B15: Risk Analyst | C15: =$C$2 -> Biomass | D15: Project Controls | E15: 0.05 | F15: 0.05 | G15: 0.05 | H15: 0.05 | I15: 0.05 | J15: 0.05 | K15: 0.05 | L15: 0.05 | M15: 0.05 | N15: 0.05 | O15: 0.05 | P15: 0.05 | Q15: 0.05 | R15: 0.05 | S15: 0.05 | T15: 0.05 | U15: 0.05 | V15: 0.05 | W15: 0.05 | X15: 0.05 | Y15: 0.05 | Z15: 0.05 | AA15: 0.05 | AB15: 0.05 | AC15: 0.05 | AD15: 0 | AE15: 0
B16: Document Control Specialist | C16: =$C$2 -> Biomass | D16: Project Controls | E16: 0.15 | F16: 0.15 | G16: 0.15 | H16: 0.15 | I16: 0.15 | J16: 0.15 | K16: 0.15 | L16: 0.15 | M16: 0.15 | N16: 0.15 | O16: 0.15 | P16: 0.15 | Q16: 0.15 | R16: 0.15 | S16: 0.15 | T16: 0.15 | U16: 0.15 | V16: 0.15 | W16: 0.15 | X16: 0.15 | Y16: 0.15 | Z16: 0.15 | AA16: 0.15 | AB16: 0.15 | AC16: 0.15 | AD16: 0.15 | AE16: 0.15
B17: Scheduler | C17: =$C$2 -> Biomass | D17: Project Controls | E17: 0.1 | F17: 0.1 | G17: 0.1 | H17: 0.1 | I17: 0.1 | J17: 0.1 | K17: 0.1 | L17: 0.1 | M17: 0.1 | N17: 0.1 | O17: 0.1 | P17: 0.1 | Q17: 0.1 | R17: 0.1 | S17: 0.1 | T17: 0.1 | U17: 0.1 | V17: 0.1 | W17: 0.1 | X17: 0.1 | Y17: 0.1 | Z17: 0.1 | AA17: 0.1 | AB17: 0.1 | AC17: 0.1 | AD17: 0.1 | AE17: 0.1
B18: Cost Controls | C18: =$C$2 -> Biomass | D18: Project Controls | E18: 0.1 | F18: 0.1 | G18: 0.1 | H18: 0.1 | I18: 0.1 | J18: 0.1 | K18: 0.1 | L18: 0.1 | M18: 0.1 | N18: 0.1 | O18: 0.1 | P18: 0.1 | Q18: 0.1 | R18: 0.1 | S18: 0.1 | T18: 0.1 | U18: 0.1 | V18: 0.1 | W18: 0.1 | X18: 0.1 | Y18: 0.1 | Z18: 0.1 | AA18: 0.1 | AB18: 0.1 | AC18: 0.1 | AD18: 0.1 | AE18: 0.1

Sheet Solar
B2: PROJECT ARCHETYPE: | C2: Solar
B4: Resource Name | C4: Project Archetype | D4: Resource Category | E4: Planning | K4: Design & Engineering | Q4: Construction | AC4: Closeout
B5: Column1 | C5: Column2 | D5: Column3 | E5: 1 | F5: 2 | G5: 3 | H5: 4 | I5: 5 | J5: 6 | K5: 7 | L5: 8 | M5: 9 | N5: 10 | O5: 11 | P5: 12 | Q5: 13 | R5: 14 | S5: 15 | T5: 16 | U5: 17 | V5: 18 | W5: 19 | X5: 20 | Y5: 21 | Z5: 22 | AA5: 23 | AB5: 24 | AC5: 25 | AD5: 26 | AE5: 27
B6: Project Manager | C6: =$C$2 -> Solar | D6: Project Management | E6: 0.25 | F6: 0.25 | G6: 0.25 | H6: 0.45 | I6: 0.45 | J6: 0.45 | K6: 0.65 | L6: 0.65 | M6: 0.65 | N6: 0.85 | O6: 0.85 | P6: 0.85 | Q6: 0.85 | R6: 0.85 | S6: 0.85 | T6: 0.85 | U6: 0.85 | V6: 0.85 | W6: 0.85 | X6: 0.85 | Y6: 0.85 | Z6: 0.85 | AA6: 0.85 | AB6: 0.85 | AC6: 0.5 | AD6: 0.4 | AE6: 0.25
B7: Project Engineer | C7: =$C$2 -> Solar | D7: Project Management | E7: 0.05 | F7: 0.05 | G7: 0.05 | H7: 0.05 | I7: 0.05 | J7: 0.05 | K7: 0.05 | L7: 0.05 | M7: 0.05 | N7: 0.05 | O7: 0.05 | P7: 0.05 | Q7: 0.05 | R7: 0.05 | S7: 0.05 | T7: 0.05 | U7: 0.05 | V7: 0.05 | W7: 0.05 | X7: 0.05 | Y7: 0.05 | Z7: 0.05 | AA7: 0.05 | AB7: 0.05 | AC7: 0.05 | AD7: 0.05 | AE7: 0.05
B8: Project Coordinator | C8: =$C$2 -> Solar | D8: Project Management | E8: 0.05 | F8: 0.05 | G8: 0.1 | H8: 0.1 | I8: 0.15 | J8: 0.15 | K8: 0.25 | L8: 0.25 | M8: 0.25 | N8: 0.25 | O8: 0.25 | P8: 0.25 | Q8: 0.25 | R8: 0.25 | S8: 0.25 | T8: 0.25 | U8: 0.25 | V8: 0.25 | W8: 0.25 | X8: 0.25 | Y8: 0.25 | Z8: 0.25 | AA8: 0.25 | AB8: 0.25 | AC8: 0.25 | AD8: 0.25 | AE8: 0.25
B9: Civil Engineer | C9: =$C$2 -> Solar | D9: Engineering | E9: 0.05 | F9: 0.05 | G9: 0.05 | H9: 0.05 | I9: 0.05 | J9: 0.05 | K9: 0.1 | L9: 0.1 | M9: 0.1 | N9: 0.1 | O9: 0.1 | P9: 0.1 | Q9: 0.1 | R9: 0.1 | S9: 0.1 | T9: 0.1 | U9: 0.1 | V9: 0.1 | W9: 0.1 | X9: 0.1 | Y9: 0.1 | Z9: 0.1 | AA9: 0.1 | AB9: 0.1 | AC9: 0.05 | AD9: 0.05 | AE9: 0
B10: I&C Engineer | C10: =$C$2 -> Solar | D10: Engineering | E10: 0.05 | F10: 0.05 | G10: 0.05 | H10: 0.05 | I10: 0.05 | J10: 0.05 | K10: 0.1 | L10: 0.1 | M10: 0.1 | N10: 0.1 | O10: 0.1 | P10: 0.1 | Q10: 0.1 | R10: 0.1 | S10: 0.1 | T10: 0.1 | U10: 0.1 | V10: 0.1 | W10: 0.1 | X10: 0.1 | Y10: 0.1 | Z10: 0.1 | AA10: 0.1 | AB10: 0.1 | AC10: 0.05 | AD10: 0.05 | AE10: 0
B11: Electrical Engineer | C11: =$C$2 -> Solar | D11: Engineering | E11: 0.05 | F11: 0.05 | G11: 0.05 | H11: 0.05 | I11: 0.05 | J11: 0.05 | K11: 0.1 | L11: 0.1 | M11: 0.1 | N11: 0.1 | O11: 0.1 | P11: 0.1 | Q11: 0.1 | R11: 0.1 | S11: 0.1 | T11: 0.1 | U11: 0.1 | V11: 0.1 | W11: 0.1 | X11: 0.1 | Y11: 0.1 | Z11: 0.1 | AA11: 0.1 | AB11: 0.1 | AC11: 0.05 | AD11: 0.05 | AE11: 0
B12: Mechanical Engineer | C12: =$C$2 -> Solar | D12: Engineering | E12: 0.05 | F12: 0.05 | G12: 0.05 | H12: 0.05 | I12: 0.05 | J12: 0.05 | K12: 0.1 | L12: 0.1 | M12: 0.1 | N12: 0.1 | O12: 0.1 | P12: 0.1 | Q12: 0.1 | R12: 0.1 | S12: 0.1 | T12: 0.1 | U12: 0.1 | V12: 0.1 | W12: 0.1 | X12: 0.1 | Y12: 0.1 | Z12: 0.1 | AA12: 0.1 | AB12: 0.1 | AC12: 0.05 | AD12: 0.05 | AE12: 0
B13: Structural Engineer | C13: =$C$2 -> Solar | D13: Engineering | E13: 0.05 | F13: 0.05 | G13: 0.05 | H13: 0.05 | I13: 0.05 | J13: 0.05 | K13: 0.1 | L13: 0.1 | M13: 0.1 | N13: 0.1 | O13: 0.1 | P13: 0.1 | Q13: 0.1 | R13: 0.1 | S13: 0.1 | T13: 0.1 | U13: 0.1 | V13: 0.1 | W13: 0.1 | X13: 0.1 | Y13: 0.1 | Z13: 0.1 | AA13: 0.1 | AB13: 0.1 | AC13: 0.05 | AD13: 0.05 | AE13: 0
B14: Construction Manager | C14: =$C$2 -> Solar | D14: Construction Monitoring | E14: 0 | F14: 0 | G14: 0 | H14: 0.25 | I14: 0.25 | J14: 0.25 | K14: 0.5 | L14: 0.5 | M14: 0.5 | N14: 0.75 | O14: 0.75 | P14: 0.75 | Q14: 0.75 | R14: 0.75 | S14: 0.75 | T14: 0.75 | U14: 0.75 | V14: 0.75 | W14: 0.75 | X14: 0.75 | Y14: 0.75 | Z14: 0.75 | AA14: 0.75 | AB14: 0.75 | AC14: 0.5 | AD14: 0.4 | AE14: 0.25
B15: H&S Field | C15: =$C$2 -> Solar | D15: Construction Monitoring | E15: 0 | F15: 0 | G15: 0 | H15: 0 | I15: 0 | J15: 0 | K15: 0 | L15: 0 | M15: 0 | N15: 0 | O15: 0 | P15: 0 | Q15: 0.5 | R15: 0.5 | S15: 0.5 | T15: 0.5 | U15: 0.5 | V15: 0.5 | W15: 0.5 | X15: 0.5 | Y15: 0.5 | Z15: 0.5 | AA15: 0.5 | AB15: 0.5 | AC15: 0.25 | AD15: 0.15 | AE15: 0
B16: Estimator | C16: =$C$2 -> Solar | D16: Project Controls | E16: 0.1 | F16: 0.1 | G16: 0.1 | H16: 0.1 | I16: 0.1 | J16: 0.1 | K16: 0.1 | L16: 0.1 | M16: 0.1 | N16: 0.1 | O16: 0.1 | P16: 0.1 | Q16: 0.1 | R16: 0.1 | S16: 0.1 | T16: 0.1 | U16: 0.1 | V16: 0.1 | W16: 0.1 | X16: 0.1 | Y16: 0.1 | Z16: 0.1 | AA16: 0.1 | AB16: 0.1 | AC16: 0.1 | AD16: 0.1 | AE16: 0.1
B17: Risk Analyst | C17: =$C$2 -> Solar | D17: Project Controls | E17: 0.05 | F17: 0.05 | G17: 0.05 | H17: 0.05 | I17: 0.05 | J17: 0.05 | K17: 0.05 | L17: 0.05 | M17: 0.05 | N17: 0.05 | O17: 0.05 | P17: 0.05 | Q17: 0.05 | R17: 0.05 | S17: 0.05 | T17: 0.05 | U17: 0.05 | V17: 0.05 | W17: 0.05 | X17: 0.05 | Y17: 0.05 | Z17: 0.05 | AA17: 0.05 | AB17: 0.05 | AC17: 0.05 | AD17: 0 | AE17: 0
... B20: Cost Controls | C20: =$C$2 -> Solar | D20: Project Controls | E20: 0.1 | F20: 0.1 | G20: 0.1 | H20: 0.1 | I20: 0.1 | J20: 0.1 | K20: 0.1 | L20: 0.1 | M20: 0.1 | N20: 0.1 | O20: 0.1 | P20: 0.1 | Q20: 0.1 | R20: 0.1 | S20: 0.1 | T20: 0.1 | U20: 0.1 | V20: 0.1 | W20: 0.1 | X20: 0.1 | Y20: 0.1 | Z20: 0.1 | AA20: 0.1 | AB20: 0.1 | AC20: 0.1 | AD20: 0.1 | AE20: 0.1

Sheet BESS
B2: PROJECT ARCHETYPE: | C2: BESS
B4: Resource Name | C4: Project Archetype | D4: Resource Category | E4: Planning | K4: Design & Engineering | Q4: Construction | AC4: Closeout
B5: Column1 | C5: Column2 | D5: Column3 | E5: 1 | F5: 2 | G5: 3 | H5: 4 | I5: 5 | J5: 6 | K5: 7 | L5: 8 | M5: 9 | N5: 10 | O5: 11 | P5: 12 | Q5: 13 | R5: 14 | S5: 15 | T5: 16 | U5: 17 | V5: 18 | W5: 19 | X5: 20 | Y5: 21 | Z5: 22 | AA5: 23 | AB5: 24 | AC5: 25 | AD5: 26 | AE5: 27
B6: Project Manager | C6: =$C$2 -> BESS | D6: Project Management | E6: 0.25 | F6: 0.25 | G6: 0.25 | H6: 0.45 | I6: 0.45 | J6: 0.45 | K6: 0.65 | L6: 0.65 | M6: 0.65 | N6: 0.85 | O6: 0.85 | P6: 0.85 | Q6: 0.85 | R6: 0.85 | S6: 0.85 | T6: 0.85 | U6: 0.85 | V6: 0.85 | W6: 0.85 | X6: 0.85 | Y6: 0.85 | Z6: 0.85 | AA6: 0.85 | AB6: 0.85 | AC6: 0.5 | AD6: 0.4 | AE6: 0.25
B7: Project Engineer | C7: =$C$2 -> BESS | D7: Project Management | E7: 0.05 | F7: 0.05 | G7: 0.05 | H7: 0.05 | I7: 0.05 | J7: 0.05 | K7: 0.05 | L7: 0.05 | M7: 0.05 | N7: 0.05 | O7: 0.05 | P7: 0.05 | Q7: 0.05 | R7: 0.05 | S7: 0.05 | T7: 0.05 | U7: 0.05 | V7: 0.05 | W7: 0.05 | X7: 0.05 | Y7: 0.05 | Z7: 0.05 | AA7: 0.05 | AB7: 0.05 | AC7: 0.05 | AD7: 0.05 | AE7: 0.05
B8: Project Coordinator | C8: =$C$2 -> BESS | D8: Project Management | E8: 0.05 | F8: 0.05 | G8: 0.1 | H8: 0.1 | I8: 0.15 | J8: 0.15 | K8: 0.25 | L8: 0.25 | M8: 0.25 | N8: 0.25 | O8: 0.25 | P8: 0.25 | Q8: 0.25 | R8: 0.25 | S8: 0.25 | T8: 0.25 | U8: 0.25 | V8: 0.25 | W8: 0.25 | X8: 0.25 | Y8: 0.25 | Z8: 0.25 | AA8: 0.25 | AB8: 0.25 | AC8: 0.25 | AD8: 0.25 | AE8: 0.25
B9: Civil Engineer | C9: =$C$2 -> BESS | D9: Engineering | E9: 0.05 | F9: 0.05 | G9: 0.05 | H9: 0.05 | I9: 0.05 | J9: 0.05 | K9: 0.1 | L9: 0.1 | M9: 0.1 | N9: 0.1 | O9: 0.1 | P9: 0.1 | Q9: 0.1 | R9: 0.1 | S9: 0.1 | T9: 0.1 | U9: 0.1 | V9: 0.1 | W9: 0.1 | X9: 0.1 | Y9: 0.1 | Z9: 0.1 | AA9: 0.1 | AB9: 0.1 | AC9: 0.05 | AD9: 0.05 | AE9: 0
B10: I&C Engineer | C10: =$C$2 -> BESS | D10: Engineering | E10: 0.05 | F10: 0.05 | G10: 0.05 | H10: 0.05 | I10: 0.05 | J10: 0.05 | K10: 0.1 | L10: 0.1 | M10: 0.1 | N10: 0.1 | O10: 0.1 | P10: 0.1 | Q10: 0.1 | R10: 0.1 | S10: 0.1 | T10: 0.1 | U10: 0.1 | V10: 0.1 | W10: 0.1 | X10: 0.1 | Y10: 0.1 | Z10: 0.1 | AA10: 0.1 | AB10: 0.1 | AC10: 0.05 | AD10: 0.05 | AE10: 0
B11: Electrical Engineer | C11: =$C$2 -> BESS | D11: Engineering | E11: 0.05 | F11: 0.05 | G11: 0.05 | H11: 0.05 | I11: 0.05 | J11: 0.05 | K11: 0.1 | L11: 0.1 | M11: 0.1 | N11: 0.1 | O11: 0.1 | P11: 0.1 | Q11: 0.1 | R11: 0.1 | S11: 0.1 | T11: 0.1 | U11: 0.1 | V11: 0.1 | W11: 0.1 | X11: 0.1 | Y11: 0.1 | Z11: 0.1 | AA11: 0.1 | AB11: 0.1 | AC11: 0.05 | AD11: 0.05 | AE11: 0
B12: Mechanical Engineer | C12: =$C$2 -> BESS | D12: Engineering | E12: 0.05 | F12: 0.05 | G12: 0.05 | H12: 0.05 | I12: 0.05 | J12: 0.05 | K12: 0.1 | L12: 0.1 | M12: 0.1 | N12: 0.1 | O12: 0.1 | P12: 0.1 | Q12: 0.1 | R12: 0.1 | S12: 0.1 | T12: 0.1 | U12: 0.1 | V12: 0.1 | W12: 0.1 | X12: 0.1 | Y12: 0.1 | Z12: 0.1 | AA12: 0.1 | AB12: 0.1 | AC12: 0.05 | AD12: 0.05 | AE12: 0
B13: Structural Engineer | C13: =$C$2 -> BESS | D13: Engineering | E13: 0.05 | F13: 0.05 | G13: 0.05 | H13: 0.05 | I13: 0.05 | J13: 0.05 | K13: 0.1 | L13: 0.1 | M13: 0.1 | N13: 0.1 | O13: 0.1 | P13: 0.1 | Q13: 0.1 | R13: 0.1 | S13: 0.1 | T13: 0.1 | U13: 0.1 | V13: 0.1 | W13: 0.1 | X13: 0.1 | Y13: 0.1 | Z13: 0.1 | AA13: 0.1 | AB13: 0.1 | AC13: 0.05 | AD13: 0.05 | AE13: 0
B14: Construction Manager | C14: =$C$2 -> BESS | D14: Construction Monitoring | E14: 0 | F14: 0 | G14: 0 | H14: 0.25 | I14: 0.25 | J14: 0.25 | K14: 0.5 | L14: 0.5 | M14: 0.5 | N14: 0.75 | O14: 0.75 | P14: 0.75 | Q14: 0.75 | R14: 0.75 | S14: 0.75 | T14: 0.75 | U14: 0.75 | V14: 0.75 | W14: 0.75 | X14: 0.75 | Y14: 0.75 | Z14: 0.75 | AA14: 0.75 | AB14: 0.75 | AC14: 0.5 | AD14: 0.4 | AE14: 0.25
B15: H&S Field | C15: =$C$2 -> BESS | D15: Construction Monitoring | E15: 0 | F15: 0 | G15: 0 | H15: 0 | I15: 0 | J15: 0 | K15: 0 | L15: 0 | M15: 0 | N15: 0 | O15: 0 | P15: 0 | Q15: 0.5 | R15: 0.5 | S15: 0.5 | T15: 0.5 | U15: 0.5 | V15: 0.5 | W15: 0.5 | X15: 0.5 | Y15: 0.5 | Z15: 0.5 | AA15: 0.5 | AB15: 0.5 | AC15: 0.25 | AD15: 0.15 | AE15: 0
B16: Estimator | C16: =$C$2 -> BESS | D16: Project Controls | E16: 0.1 | F16: 0.1 | G16: 0.1 | H16: 0.1 | I16: 0.1 | J16: 0.1 | K16: 0.1 | L16: 0.1 | M16: 0.1 | N16: 0.1 | O16: 0.1 | P16: 0.1 | Q16: 0.1 | R16: 0.1 | S16: 0.1 | T16: 0.1 | U16: 0.1 | V16: 0.1 | W16: 0.1 | X16: 0.1 | Y16: 0.1 | Z16: 0.1 | AA16: 0.1 | AB16: 0.1 | AC16: 0.1 | AD16: 0.1 | AE16: 0.1
B17: Risk Analyst | C17: =$C$2 -> BESS | D17: Project Controls | E17: 0.05 | F17: 0.05 | G17: 0.05 | H17: 0.05 | I17: 0.05 | J17: 0.05 | K17: 0.05 | L17: 0.05 | M17: 0.05 | N17: 0.05 | O17: 0.05 | P17: 0.05 | Q17: 0.05 | R17: 0.05 | S17: 0.05 | T17: 0.05 | U17: 0.05 | V17: 0.05 | W17: 0.05 | X17: 0.05 | Y17: 0.05 | Z17: 0.05 | AA17: 0.05 | AB17: 0.05 | AC17: 0.05 | AD17: 0 | AE17: 0
... B20: Cost Controls | C20: =$C$2 -> BESS | D20: Project Controls | E20: 0.1 | F20: 0.1 | G20: 0.1 | H20: 0.1 | I20: 0.1 | J20: 0.1 | K20: 0.1 | L20: 0.1 | M20: 0.1 | N20: 0.1 | O20: 0.1 | P20: 0.1 | Q20: 0.1 | R20: 0.1 | S20: 0.1 | T20: 0.1 | U20: 0.1 | V20: 0.1 | W20: 0.1 | X20: 0.1 | Y20: 0.1 | Z20: 0.1 | AA20: 0.1 | AB20: 0.1 | AC20: 0.1 | AD20: 0.1 | AE20: 0.1

Sheet New Archetype 1
B2: PROJECT ARCHETYPE: | C2: ='Duration Table'!C16 -> New Archetype 1
B4: Resource Name | C4: Project Archetype | D4: Resource Category | E4: Planning | K4: Design & Engineering | Q4: Construction | AC4: Closeout
B5: Column1 | C5: Column2 | D5: Column3 | E5: 1 | F5: 2 | G5: 3 | H5: 4 | I5: 5 | J5: 6 | K5: 7 | L5: 8 | M5: 9 | N5: 10 | O5: 11 | P5: 12 | Q5: 13 | R5: 14 | S5: 15 | T5: 16 | U5: 17 | V5: 18 | W5: 19 | X5: 20 | Y5: 21 | Z5: 22 | AA5: 23 | AB5: 24 | AC5: 25 | AD5: 26 | AE5: 27
B6: Project Manager | C6: =$C$2 -> New Archetype 1 | D6: Project Management
B7: Project Engineer | C7: =$C$2 -> New Archetype 1 | D7: Project Management
B8: Project Coordinator | C8: =$C$2 -> New Archetype 1 | D8: Project Management
B9: Civil Engineer | C9: =$C$2 -> New Archetype 1 | D9: Engineering
B10: I&C Engineer | C10: =$C$2 -> New Archetype 1 | D10: Engineering
B11: Electrical Engineer | C11: =$C$2 -> New Archetype 1 | D11: Engineering
B12: Mechanical Engineer | C12: =$C$2 -> New Archetype 1 | D12: Engineering
B13: Structural Engineer | C13: =$C$2 -> New Archetype 1 | D13: Engineering
B14: Construction Manager | C14: =$C$2 -> New Archetype 1 | D14: Construction Monitoring
B15: H&S Field | C15: =$C$2 -> New Archetype 1 | D15: Construction Monitoring
B16: Estimator | C16: =$C$2 -> New Archetype 1 | D16: Project Controls
B17: Risk Analyst | C17: =$C$2 -> New Archetype 1 | D17: Project Controls
... B20: Cost Controls | C20: =$C$2 -> New Archetype 1 | D20: Project Controls

Sheet New Archetype 2
B2: PROJECT ARCHETYPE: | C2: ='Duration Table'!C17 -> New Archetype 2
B4: Resource Name | C4: Project Archetype | D4: Resource Category | E4: Planning | K4: Design & Engineering | Q4: Construction | AC4: Closeout
B5: Column1 | C5: Column2 | D5: Column3 | E5: 1 | F5: 2 | G5: 3 | H5: 4 | I5: 5 | J5: 6 | K5: 7 | L5: 8 | M5: 9 | N5: 10 | O5: 11 | P5: 12 | Q5: 13 | R5: 14 | S5: 15 | T5: 16 | U5: 17 | V5: 18 | W5: 19 | X5: 20 | Y5: 21 | Z5: 22 | AA5: 23 | AB5: 24 | AC5: 25 | AD5: 26 | AE5: 27
B6: Project Manager | C6: =$C$2 -> New Archetype 2 | D6: Project Management
B7: Project Engineer | C7: =$C$2 -> New Archetype 2 | D7: Project Management
B8: Project Coordinator | C8: =$C$2 -> New Archetype 2 | D8: Project Management
B9: Civil Engineer | C9: =$C$2 -> New Archetype 2 | D9: Engineering
B10: I&C Engineer | C10: =$C$2 -> New Archetype 2 | D10: Engineering
B11: Electrical Engineer | C11: =$C$2 -> New Archetype 2 | D11: Engineering
B12: Mechanical Engineer | C12: =$C$2 -> New Archetype 2 | D12: Engineering
B13: Structural Engineer | C13: =$C$2 -> New Archetype 2 | D13: Engineering
B14: Construction Manager | C14: =$C$2 -> New Archetype 2 | D14: Construction Monitoring
B15: H&S Field | C15: =$C$2 -> New Archetype 2 | D15: Construction Monitoring
B16: Estimator | C16: =$C$2 -> New Archetype 2 | D16: Project Controls
